ERROR 2020-04-18 23:48:43,685 log 1072 140082853144384 Internal Server Error: /customer_interface/menu/ 
Traceback (most recent call last):
  File "/home/admintrud/.local/lib/python3.6/site-packages/urllib3/connection.py", line 160, in _new_conn
    (self._dns_host, self.port), self.timeout, **extra_kw
  File "/home/admintrud/.local/lib/python3.6/site-packages/urllib3/util/connection.py", line 84, in create_connection
    raise err
  File "/home/admintrud/.local/lib/python3.6/site-packages/urllib3/util/connection.py", line 74, in create_connection
    sock.connect(sa)
ConnectionRefusedError: [Errno 111] Connection refused

During handling of the above exception, another exception occurred:

Traceback (most recent call last):
  File "/home/admintrud/.local/lib/python3.6/site-packages/urllib3/connectionpool.py", line 677, in urlopen
    chunked=chunked,
  File "/home/admintrud/.local/lib/python3.6/site-packages/urllib3/connectionpool.py", line 392, in _make_request
    conn.request(method, url, **httplib_request_kw)
  File "/usr/lib/python3.6/http/client.py", line 1254, in request
    self._send_request(method, url, body, headers, encode_chunked)
  File "/usr/lib/python3.6/http/client.py", line 1300, in _send_request
    self.endheaders(body, encode_chunked=encode_chunked)
  File "/usr/lib/python3.6/http/client.py", line 1249, in endheaders
    self._send_output(message_body, encode_chunked=encode_chunked)
  File "/usr/lib/python3.6/http/client.py", line 1036, in _send_output
    self.send(msg)
  File "/usr/lib/python3.6/http/client.py", line 974, in send
    self.connect()
  File "/home/admintrud/.local/lib/python3.6/site-packages/urllib3/connection.py", line 187, in connect
    conn = self._new_conn()
  File "/home/admintrud/.local/lib/python3.6/site-packages/urllib3/connection.py", line 172, in _new_conn
    self, "Failed to establish a new connection: %s" % e
urllib3.exceptions.NewConnectionError: <urllib3.connection.HTTPConnection object at 0x7f678c329710>: Failed to establish a new connection: [Errno 111] Connection refused

During handling of the above exception, another exception occurred:

Traceback (most recent call last):
  File "/home/admintrud/.local/lib/python3.6/site-packages/requests/adapters.py", line 449, in send
    timeout=timeout
  File "/home/admintrud/.local/lib/python3.6/site-packages/urllib3/connectionpool.py", line 725, in urlopen
    method, url, error=e, _pool=self, _stacktrace=sys.exc_info()[2]
  File "/home/admintrud/.local/lib/python3.6/site-packages/urllib3/util/retry.py", line 439, in increment
    raise MaxRetryError(_pool, url, error or ResponseError(cause))
urllib3.exceptions.MaxRetryError: HTTPConnectionPool(host='127.0.0.1', port=8000): Max retries exceeded with url: /shaw_queue/get_customers_menu/ (Caused by NewConnectionError('<urllib3.connection.HTTPConnection object at 0x7f678c329710>: Failed to establish a new connection: [Errno 111] Connection refused',))

During handling of the above exception, another exception occurred:

Traceback (most recent call last):
  File "/home/admintrud/.local/lib/python3.6/site-packages/django/core/handlers/exception.py", line 34, in inner
    response = get_response(request)
  File "/home/admintrud/.local/lib/python3.6/site-packages/django/core/handlers/base.py", line 115, in _get_response
    response = self.process_exception_by_middleware(e, request)
  File "/home/admintrud/.local/lib/python3.6/site-packages/django/core/handlers/base.py", line 113, in _get_response
    response = wrapped_callback(request, *callback_args, **callback_kwargs)
  File "/home/admintrud/front/shawarma_site/customer_interface/views.py", line 74, in menu
    context = get_menu()
  File "/home/admintrud/front/shawarma_site/customer_interface/views.py", line 186, in get_menu
    result = requests.get(GET_MENU_URL)
  File "/home/admintrud/.local/lib/python3.6/site-packages/requests/api.py", line 76, in get
    return request('get', url, params=params, **kwargs)
  File "/home/admintrud/.local/lib/python3.6/site-packages/requests/api.py", line 61, in request
    return session.request(method=method, url=url, **kwargs)
  File "/home/admintrud/.local/lib/python3.6/site-packages/requests/sessions.py", line 530, in request
    resp = self.send(prep, **send_kwargs)
  File "/home/admintrud/.local/lib/python3.6/site-packages/requests/sessions.py", line 643, in send
    r = adapter.send(request, **kwargs)
  File "/home/admintrud/.local/lib/python3.6/site-packages/requests/adapters.py", line 516, in send
    raise ConnectionError(e, request=request)
requests.exceptions.ConnectionError: HTTPConnectionPool(host='127.0.0.1', port=8000): Max retries exceeded with url: /shaw_queue/get_customers_menu/ (Caused by NewConnectionError('<urllib3.connection.HTTPConnection object at 0x7f678c329710>: Failed to establish a new connection: [Errno 111] Connection refused',))
ERROR 2020-04-24 23:55:36,948 log 24948 140558047455040 Internal Server Error: /customer_interface/menu/ 
Traceback (most recent call last):
  File "/home/admintrud/.local/lib/python3.6/site-packages/urllib3/connection.py", line 160, in _new_conn
    (self._dns_host, self.port), self.timeout, **extra_kw
  File "/home/admintrud/.local/lib/python3.6/site-packages/urllib3/util/connection.py", line 84, in create_connection
    raise err
  File "/home/admintrud/.local/lib/python3.6/site-packages/urllib3/util/connection.py", line 74, in create_connection
    sock.connect(sa)
ConnectionRefusedError: [Errno 111] Connection refused

During handling of the above exception, another exception occurred:

Traceback (most recent call last):
  File "/home/admintrud/.local/lib/python3.6/site-packages/urllib3/connectionpool.py", line 677, in urlopen
    chunked=chunked,
  File "/home/admintrud/.local/lib/python3.6/site-packages/urllib3/connectionpool.py", line 392, in _make_request
    conn.request(method, url, **httplib_request_kw)
  File "/usr/lib/python3.6/http/client.py", line 1264, in request
    self._send_request(method, url, body, headers, encode_chunked)
  File "/usr/lib/python3.6/http/client.py", line 1310, in _send_request
    self.endheaders(body, encode_chunked=encode_chunked)
  File "/usr/lib/python3.6/http/client.py", line 1259, in endheaders
    self._send_output(message_body, encode_chunked=encode_chunked)
  File "/usr/lib/python3.6/http/client.py", line 1038, in _send_output
    self.send(msg)
  File "/usr/lib/python3.6/http/client.py", line 976, in send
    self.connect()
  File "/home/admintrud/.local/lib/python3.6/site-packages/urllib3/connection.py", line 187, in connect
    conn = self._new_conn()
  File "/home/admintrud/.local/lib/python3.6/site-packages/urllib3/connection.py", line 172, in _new_conn
    self, "Failed to establish a new connection: %s" % e
urllib3.exceptions.NewConnectionError: <urllib3.connection.HTTPConnection object at 0x7fd62ffc1b38>: Failed to establish a new connection: [Errno 111] Connection refused

During handling of the above exception, another exception occurred:

Traceback (most recent call last):
  File "/home/admintrud/.local/lib/python3.6/site-packages/requests/adapters.py", line 449, in send
    timeout=timeout
  File "/home/admintrud/.local/lib/python3.6/site-packages/urllib3/connectionpool.py", line 725, in urlopen
    method, url, error=e, _pool=self, _stacktrace=sys.exc_info()[2]
  File "/home/admintrud/.local/lib/python3.6/site-packages/urllib3/util/retry.py", line 439, in increment
    raise MaxRetryError(_pool, url, error or ResponseError(cause))
urllib3.exceptions.MaxRetryError: HTTPConnectionPool(host='127.0.0.1', port=8000): Max retries exceeded with url: /shaw_queue/get_customers_menu/ (Caused by NewConnectionError('<urllib3.connection.HTTPConnection object at 0x7fd62ffc1b38>: Failed to establish a new connection: [Errno 111] Connection refused',))

During handling of the above exception, another exception occurred:

Traceback (most recent call last):
  File "/home/admintrud/.local/lib/python3.6/site-packages/django/core/handlers/exception.py", line 34, in inner
    response = get_response(request)
  File "/home/admintrud/.local/lib/python3.6/site-packages/django/core/handlers/base.py", line 115, in _get_response
    response = self.process_exception_by_middleware(e, request)
  File "/home/admintrud/.local/lib/python3.6/site-packages/django/core/handlers/base.py", line 113, in _get_response
    response = wrapped_callback(request, *callback_args, **callback_kwargs)
  File "/home/admintrud/front/shawarma_site/customer_interface/views.py", line 74, in menu
    context = get_menu()
  File "/home/admintrud/front/shawarma_site/customer_interface/views.py", line 186, in get_menu
    result = requests.get(GET_MENU_URL)
  File "/home/admintrud/.local/lib/python3.6/site-packages/requests/api.py", line 76, in get
    return request('get', url, params=params, **kwargs)
  File "/home/admintrud/.local/lib/python3.6/site-packages/requests/api.py", line 61, in request
    return session.request(method=method, url=url, **kwargs)
  File "/home/admintrud/.local/lib/python3.6/site-packages/requests/sessions.py", line 530, in request
    resp = self.send(prep, **send_kwargs)
  File "/home/admintrud/.local/lib/python3.6/site-packages/requests/sessions.py", line 643, in send
    r = adapter.send(request, **kwargs)
  File "/home/admintrud/.local/lib/python3.6/site-packages/requests/adapters.py", line 516, in send
    raise ConnectionError(e, request=request)
requests.exceptions.ConnectionError: HTTPConnectionPool(host='127.0.0.1', port=8000): Max retries exceeded with url: /shaw_queue/get_customers_menu/ (Caused by NewConnectionError('<urllib3.connection.HTTPConnection object at 0x7fd62ffc1b38>: Failed to establish a new connection: [Errno 111] Connection refused',))
ERROR 2020-04-24 23:55:47,213 log 24948 140558047455040 Internal Server Error: /customer_interface/menu/ 
Traceback (most recent call last):
  File "/home/admintrud/.local/lib/python3.6/site-packages/urllib3/connection.py", line 160, in _new_conn
    (self._dns_host, self.port), self.timeout, **extra_kw
  File "/home/admintrud/.local/lib/python3.6/site-packages/urllib3/util/connection.py", line 84, in create_connection
    raise err
  File "/home/admintrud/.local/lib/python3.6/site-packages/urllib3/util/connection.py", line 74, in create_connection
    sock.connect(sa)
ConnectionRefusedError: [Errno 111] Connection refused

During handling of the above exception, another exception occurred:

Traceback (most recent call last):
  File "/home/admintrud/.local/lib/python3.6/site-packages/urllib3/connectionpool.py", line 677, in urlopen
    chunked=chunked,
  File "/home/admintrud/.local/lib/python3.6/site-packages/urllib3/connectionpool.py", line 392, in _make_request
    conn.request(method, url, **httplib_request_kw)
  File "/usr/lib/python3.6/http/client.py", line 1264, in request
    self._send_request(method, url, body, headers, encode_chunked)
  File "/usr/lib/python3.6/http/client.py", line 1310, in _send_request
    self.endheaders(body, encode_chunked=encode_chunked)
  File "/usr/lib/python3.6/http/client.py", line 1259, in endheaders
    self._send_output(message_body, encode_chunked=encode_chunked)
  File "/usr/lib/python3.6/http/client.py", line 1038, in _send_output
    self.send(msg)
  File "/usr/lib/python3.6/http/client.py", line 976, in send
    self.connect()
  File "/home/admintrud/.local/lib/python3.6/site-packages/urllib3/connection.py", line 187, in connect
    conn = self._new_conn()
  File "/home/admintrud/.local/lib/python3.6/site-packages/urllib3/connection.py", line 172, in _new_conn
    self, "Failed to establish a new connection: %s" % e
urllib3.exceptions.NewConnectionError: <urllib3.connection.HTTPConnection object at 0x7fd62ff14828>: Failed to establish a new connection: [Errno 111] Connection refused

During handling of the above exception, another exception occurred:

Traceback (most recent call last):
  File "/home/admintrud/.local/lib/python3.6/site-packages/requests/adapters.py", line 449, in send
    timeout=timeout
  File "/home/admintrud/.local/lib/python3.6/site-packages/urllib3/connectionpool.py", line 725, in urlopen
    method, url, error=e, _pool=self, _stacktrace=sys.exc_info()[2]
  File "/home/admintrud/.local/lib/python3.6/site-packages/urllib3/util/retry.py", line 439, in increment
    raise MaxRetryError(_pool, url, error or ResponseError(cause))
urllib3.exceptions.MaxRetryError: HTTPConnectionPool(host='127.0.0.1', port=8000): Max retries exceeded with url: /shaw_queue/get_customers_menu/ (Caused by NewConnectionError('<urllib3.connection.HTTPConnection object at 0x7fd62ff14828>: Failed to establish a new connection: [Errno 111] Connection refused',))

During handling of the above exception, another exception occurred:

Traceback (most recent call last):
  File "/home/admintrud/.local/lib/python3.6/site-packages/django/core/handlers/exception.py", line 34, in inner
    response = get_response(request)
  File "/home/admintrud/.local/lib/python3.6/site-packages/django/core/handlers/base.py", line 115, in _get_response
    response = self.process_exception_by_middleware(e, request)
  File "/home/admintrud/.local/lib/python3.6/site-packages/django/core/handlers/base.py", line 113, in _get_response
    response = wrapped_callback(request, *callback_args, **callback_kwargs)
  File "/home/admintrud/front/shawarma_site/customer_interface/views.py", line 74, in menu
    context = get_menu()
  File "/home/admintrud/front/shawarma_site/customer_interface/views.py", line 186, in get_menu
    result = requests.get(GET_MENU_URL)
  File "/home/admintrud/.local/lib/python3.6/site-packages/requests/api.py", line 76, in get
    return request('get', url, params=params, **kwargs)
  File "/home/admintrud/.local/lib/python3.6/site-packages/requests/api.py", line 61, in request
    return session.request(method=method, url=url, **kwargs)
  File "/home/admintrud/.local/lib/python3.6/site-packages/requests/sessions.py", line 530, in request
    resp = self.send(prep, **send_kwargs)
  File "/home/admintrud/.local/lib/python3.6/site-packages/raven/breadcrumbs.py", line 341, in send
    resp = real_send(self, request, *args, **kwargs)
  File "/home/admintrud/.local/lib/python3.6/site-packages/requests/sessions.py", line 643, in send
    r = adapter.send(request, **kwargs)
  File "/home/admintrud/.local/lib/python3.6/site-packages/requests/adapters.py", line 516, in send
    raise ConnectionError(e, request=request)
requests.exceptions.ConnectionError: HTTPConnectionPool(host='127.0.0.1', port=8000): Max retries exceeded with url: /shaw_queue/get_customers_menu/ (Caused by NewConnectionError('<urllib3.connection.HTTPConnection object at 0x7fd62ff14828>: Failed to establish a new connection: [Errno 111] Connection refused',))
ERROR 2020-04-24 23:56:17,514 log 24948 140558047455040 Internal Server Error: /customer_interface/menu/ 
Traceback (most recent call last):
  File "/home/admintrud/.local/lib/python3.6/site-packages/urllib3/connection.py", line 160, in _new_conn
    (self._dns_host, self.port), self.timeout, **extra_kw
  File "/home/admintrud/.local/lib/python3.6/site-packages/urllib3/util/connection.py", line 84, in create_connection
    raise err
  File "/home/admintrud/.local/lib/python3.6/site-packages/urllib3/util/connection.py", line 74, in create_connection
    sock.connect(sa)
ConnectionRefusedError: [Errno 111] Connection refused

During handling of the above exception, another exception occurred:

Traceback (most recent call last):
  File "/home/admintrud/.local/lib/python3.6/site-packages/urllib3/connectionpool.py", line 677, in urlopen
    chunked=chunked,
  File "/home/admintrud/.local/lib/python3.6/site-packages/urllib3/connectionpool.py", line 392, in _make_request
    conn.request(method, url, **httplib_request_kw)
  File "/usr/lib/python3.6/http/client.py", line 1264, in request
    self._send_request(method, url, body, headers, encode_chunked)
  File "/usr/lib/python3.6/http/client.py", line 1310, in _send_request
    self.endheaders(body, encode_chunked=encode_chunked)
  File "/usr/lib/python3.6/http/client.py", line 1259, in endheaders
    self._send_output(message_body, encode_chunked=encode_chunked)
  File "/usr/lib/python3.6/http/client.py", line 1038, in _send_output
    self.send(msg)
  File "/usr/lib/python3.6/http/client.py", line 976, in send
    self.connect()
  File "/home/admintrud/.local/lib/python3.6/site-packages/urllib3/connection.py", line 187, in connect
    conn = self._new_conn()
  File "/home/admintrud/.local/lib/python3.6/site-packages/urllib3/connection.py", line 172, in _new_conn
    self, "Failed to establish a new connection: %s" % e
urllib3.exceptions.NewConnectionError: <urllib3.connection.HTTPConnection object at 0x7fd63001b940>: Failed to establish a new connection: [Errno 111] Connection refused

During handling of the above exception, another exception occurred:

Traceback (most recent call last):
  File "/home/admintrud/.local/lib/python3.6/site-packages/requests/adapters.py", line 449, in send
    timeout=timeout
  File "/home/admintrud/.local/lib/python3.6/site-packages/urllib3/connectionpool.py", line 725, in urlopen
    method, url, error=e, _pool=self, _stacktrace=sys.exc_info()[2]
  File "/home/admintrud/.local/lib/python3.6/site-packages/urllib3/util/retry.py", line 439, in increment
    raise MaxRetryError(_pool, url, error or ResponseError(cause))
urllib3.exceptions.MaxRetryError: HTTPConnectionPool(host='127.0.0.1', port=8000): Max retries exceeded with url: /shaw_queue/get_customers_menu/ (Caused by NewConnectionError('<urllib3.connection.HTTPConnection object at 0x7fd63001b940>: Failed to establish a new connection: [Errno 111] Connection refused',))

During handling of the above exception, another exception occurred:

Traceback (most recent call last):
  File "/home/admintrud/.local/lib/python3.6/site-packages/django/core/handlers/exception.py", line 34, in inner
    response = get_response(request)
  File "/home/admintrud/.local/lib/python3.6/site-packages/django/core/handlers/base.py", line 115, in _get_response
    response = self.process_exception_by_middleware(e, request)
  File "/home/admintrud/.local/lib/python3.6/site-packages/django/core/handlers/base.py", line 113, in _get_response
    response = wrapped_callback(request, *callback_args, **callback_kwargs)
  File "/home/admintrud/front/shawarma_site/customer_interface/views.py", line 74, in menu
    context = get_menu()
  File "/home/admintrud/front/shawarma_site/customer_interface/views.py", line 186, in get_menu
    result = requests.get(GET_MENU_URL)
  File "/home/admintrud/.local/lib/python3.6/site-packages/requests/api.py", line 76, in get
    return request('get', url, params=params, **kwargs)
  File "/home/admintrud/.local/lib/python3.6/site-packages/requests/api.py", line 61, in request
    return session.request(method=method, url=url, **kwargs)
  File "/home/admintrud/.local/lib/python3.6/site-packages/requests/sessions.py", line 530, in request
    resp = self.send(prep, **send_kwargs)
  File "/home/admintrud/.local/lib/python3.6/site-packages/raven/breadcrumbs.py", line 341, in send
    resp = real_send(self, request, *args, **kwargs)
  File "/home/admintrud/.local/lib/python3.6/site-packages/requests/sessions.py", line 643, in send
    r = adapter.send(request, **kwargs)
  File "/home/admintrud/.local/lib/python3.6/site-packages/requests/adapters.py", line 516, in send
    raise ConnectionError(e, request=request)
requests.exceptions.ConnectionError: HTTPConnectionPool(host='127.0.0.1', port=8000): Max retries exceeded with url: /shaw_queue/get_customers_menu/ (Caused by NewConnectionError('<urllib3.connection.HTTPConnection object at 0x7fd63001b940>: Failed to establish a new connection: [Errno 111] Connection refused',))
ERROR 2020-04-24 23:57:39,355 log 24942 140558047455040 Internal Server Error: /customer_interface/menu/ 
Traceback (most recent call last):
  File "/home/admintrud/.local/lib/python3.6/site-packages/urllib3/connection.py", line 160, in _new_conn
    (self._dns_host, self.port), self.timeout, **extra_kw
  File "/home/admintrud/.local/lib/python3.6/site-packages/urllib3/util/connection.py", line 84, in create_connection
    raise err
  File "/home/admintrud/.local/lib/python3.6/site-packages/urllib3/util/connection.py", line 74, in create_connection
    sock.connect(sa)
ConnectionRefusedError: [Errno 111] Connection refused

During handling of the above exception, another exception occurred:

Traceback (most recent call last):
  File "/home/admintrud/.local/lib/python3.6/site-packages/urllib3/connectionpool.py", line 677, in urlopen
    chunked=chunked,
  File "/home/admintrud/.local/lib/python3.6/site-packages/urllib3/connectionpool.py", line 392, in _make_request
    conn.request(method, url, **httplib_request_kw)
  File "/usr/lib/python3.6/http/client.py", line 1264, in request
    self._send_request(method, url, body, headers, encode_chunked)
  File "/usr/lib/python3.6/http/client.py", line 1310, in _send_request
    self.endheaders(body, encode_chunked=encode_chunked)
  File "/usr/lib/python3.6/http/client.py", line 1259, in endheaders
    self._send_output(message_body, encode_chunked=encode_chunked)
  File "/usr/lib/python3.6/http/client.py", line 1038, in _send_output
    self.send(msg)
  File "/usr/lib/python3.6/http/client.py", line 976, in send
    self.connect()
  File "/home/admintrud/.local/lib/python3.6/site-packages/urllib3/connection.py", line 187, in connect
    conn = self._new_conn()
  File "/home/admintrud/.local/lib/python3.6/site-packages/urllib3/connection.py", line 172, in _new_conn
    self, "Failed to establish a new connection: %s" % e
urllib3.exceptions.NewConnectionError: <urllib3.connection.HTTPConnection object at 0x7fd62ffffe10>: Failed to establish a new connection: [Errno 111] Connection refused

During handling of the above exception, another exception occurred:

Traceback (most recent call last):
  File "/home/admintrud/.local/lib/python3.6/site-packages/requests/adapters.py", line 449, in send
    timeout=timeout
  File "/home/admintrud/.local/lib/python3.6/site-packages/urllib3/connectionpool.py", line 725, in urlopen
    method, url, error=e, _pool=self, _stacktrace=sys.exc_info()[2]
  File "/home/admintrud/.local/lib/python3.6/site-packages/urllib3/util/retry.py", line 439, in increment
    raise MaxRetryError(_pool, url, error or ResponseError(cause))
urllib3.exceptions.MaxRetryError: HTTPConnectionPool(host='127.0.0.1', port=8000): Max retries exceeded with url: /shaw_queue/get_customers_menu/ (Caused by NewConnectionError('<urllib3.connection.HTTPConnection object at 0x7fd62ffffe10>: Failed to establish a new connection: [Errno 111] Connection refused',))

During handling of the above exception, another exception occurred:

Traceback (most recent call last):
  File "/home/admintrud/.local/lib/python3.6/site-packages/django/core/handlers/exception.py", line 34, in inner
    response = get_response(request)
  File "/home/admintrud/.local/lib/python3.6/site-packages/django/core/handlers/base.py", line 115, in _get_response
    response = self.process_exception_by_middleware(e, request)
  File "/home/admintrud/.local/lib/python3.6/site-packages/django/core/handlers/base.py", line 113, in _get_response
    response = wrapped_callback(request, *callback_args, **callback_kwargs)
  File "/home/admintrud/front/shawarma_site/customer_interface/views.py", line 74, in menu
    context = get_menu()
  File "/home/admintrud/front/shawarma_site/customer_interface/views.py", line 186, in get_menu
    result = requests.get(GET_MENU_URL)
  File "/home/admintrud/.local/lib/python3.6/site-packages/requests/api.py", line 76, in get
    return request('get', url, params=params, **kwargs)
  File "/home/admintrud/.local/lib/python3.6/site-packages/requests/api.py", line 61, in request
    return session.request(method=method, url=url, **kwargs)
  File "/home/admintrud/.local/lib/python3.6/site-packages/requests/sessions.py", line 530, in request
    resp = self.send(prep, **send_kwargs)
  File "/home/admintrud/.local/lib/python3.6/site-packages/requests/sessions.py", line 643, in send
    r = adapter.send(request, **kwargs)
  File "/home/admintrud/.local/lib/python3.6/site-packages/requests/adapters.py", line 516, in send
    raise ConnectionError(e, request=request)
requests.exceptions.ConnectionError: HTTPConnectionPool(host='127.0.0.1', port=8000): Max retries exceeded with url: /shaw_queue/get_customers_menu/ (Caused by NewConnectionError('<urllib3.connection.HTTPConnection object at 0x7fd62ffffe10>: Failed to establish a new connection: [Errno 111] Connection refused',))
ERROR 2021-03-15 20:35:21,269 log 30608 140590685177664 Internal Server Error: / 
Traceback (most recent call last):
  File "/home/admintrud/.local/lib/python3.6/site-packages/django/core/handlers/exception.py", line 34, in inner
    response = get_response(request)
  File "/home/admintrud/.local/lib/python3.6/site-packages/django/core/handlers/base.py", line 100, in _get_response
    resolver_match = resolver.resolve(request.path_info)
  File "/home/admintrud/.local/lib/python3.6/site-packages/django/urls/resolvers.py", line 544, in resolve
    for pattern in self.url_patterns:
  File "/home/admintrud/.local/lib/python3.6/site-packages/django/utils/functional.py", line 48, in __get__
    res = instance.__dict__[self.name] = self.func(instance)
  File "/home/admintrud/.local/lib/python3.6/site-packages/django/urls/resolvers.py", line 588, in url_patterns
    patterns = getattr(self.urlconf_module, "urlpatterns", self.urlconf_module)
  File "/home/admintrud/.local/lib/python3.6/site-packages/django/utils/functional.py", line 48, in __get__
    res = instance.__dict__[self.name] = self.func(instance)
  File "/home/admintrud/.local/lib/python3.6/site-packages/django/urls/resolvers.py", line 581, in urlconf_module
    return import_module(self.urlconf_name)
  File "/usr/lib/python3.6/importlib/__init__.py", line 126, in import_module
    return _bootstrap._gcd_import(name[level:], package, level)
  File "<frozen importlib._bootstrap>", line 994, in _gcd_import
  File "<frozen importlib._bootstrap>", line 971, in _find_and_load
  File "<frozen importlib._bootstrap>", line 955, in _find_and_load_unlocked
  File "<frozen importlib._bootstrap>", line 665, in _load_unlocked
  File "<frozen importlib._bootstrap_external>", line 678, in exec_module
  File "<frozen importlib._bootstrap>", line 219, in _call_with_frames_removed
  File "/home/admintrud/front/shawarma_site/shawarma_site/urls.py", line 25, in <module>
    url(r'^customer_interface/', include('customer_interface.urls')),
  File "/home/admintrud/.local/lib/python3.6/site-packages/django/urls/conf.py", line 34, in include
    urlconf_module = import_module(urlconf_module)
  File "/usr/lib/python3.6/importlib/__init__.py", line 126, in import_module
    return _bootstrap._gcd_import(name[level:], package, level)
  File "<frozen importlib._bootstrap>", line 994, in _gcd_import
  File "<frozen importlib._bootstrap>", line 971, in _find_and_load
  File "<frozen importlib._bootstrap>", line 955, in _find_and_load_unlocked
  File "<frozen importlib._bootstrap>", line 665, in _load_unlocked
  File "<frozen importlib._bootstrap_external>", line 678, in exec_module
  File "<frozen importlib._bootstrap>", line 219, in _call_with_frames_removed
  File "/home/admintrud/front/shawarma_site/customer_interface/urls.py", line 3, in <module>
    from . import views
  File "/home/admintrud/front/shawarma_site/customer_interface/views.py", line 3, in <module>
    from slugify import slugify
ModuleNotFoundError: No module named 'slugify'
ERROR 2021-03-15 20:38:41,503 log 30712 140583073986368 Internal Server Error: / 
Traceback (most recent call last):
  File "/home/admintrud/.local/lib/python3.6/site-packages/django/core/handlers/exception.py", line 34, in inner
    response = get_response(request)
  File "/home/admintrud/.local/lib/python3.6/site-packages/django/core/handlers/base.py", line 100, in _get_response
    resolver_match = resolver.resolve(request.path_info)
  File "/home/admintrud/.local/lib/python3.6/site-packages/django/urls/resolvers.py", line 544, in resolve
    for pattern in self.url_patterns:
  File "/home/admintrud/.local/lib/python3.6/site-packages/django/utils/functional.py", line 48, in __get__
    res = instance.__dict__[self.name] = self.func(instance)
  File "/home/admintrud/.local/lib/python3.6/site-packages/django/urls/resolvers.py", line 588, in url_patterns
    patterns = getattr(self.urlconf_module, "urlpatterns", self.urlconf_module)
  File "/home/admintrud/.local/lib/python3.6/site-packages/django/utils/functional.py", line 48, in __get__
    res = instance.__dict__[self.name] = self.func(instance)
  File "/home/admintrud/.local/lib/python3.6/site-packages/django/urls/resolvers.py", line 581, in urlconf_module
    return import_module(self.urlconf_name)
  File "/usr/lib/python3.6/importlib/__init__.py", line 126, in import_module
    return _bootstrap._gcd_import(name[level:], package, level)
  File "<frozen importlib._bootstrap>", line 994, in _gcd_import
  File "<frozen importlib._bootstrap>", line 971, in _find_and_load
  File "<frozen importlib._bootstrap>", line 955, in _find_and_load_unlocked
  File "<frozen importlib._bootstrap>", line 665, in _load_unlocked
  File "<frozen importlib._bootstrap_external>", line 678, in exec_module
  File "<frozen importlib._bootstrap>", line 219, in _call_with_frames_removed
  File "/home/admintrud/front/shawarma_site/shawarma_site/urls.py", line 25, in <module>
    url(r'^customer_interface/', include('customer_interface.urls')),
  File "/home/admintrud/.local/lib/python3.6/site-packages/django/urls/conf.py", line 34, in include
    urlconf_module = import_module(urlconf_module)
  File "/usr/lib/python3.6/importlib/__init__.py", line 126, in import_module
    return _bootstrap._gcd_import(name[level:], package, level)
  File "<frozen importlib._bootstrap>", line 994, in _gcd_import
  File "<frozen importlib._bootstrap>", line 971, in _find_and_load
  File "<frozen importlib._bootstrap>", line 955, in _find_and_load_unlocked
  File "<frozen importlib._bootstrap>", line 665, in _load_unlocked
  File "<frozen importlib._bootstrap_external>", line 678, in exec_module
  File "<frozen importlib._bootstrap>", line 219, in _call_with_frames_removed
  File "/home/admintrud/front/shawarma_site/customer_interface/urls.py", line 3, in <module>
    from . import views
  File "/home/admintrud/front/shawarma_site/customer_interface/views.py", line 3, in <module>
    from slugify import slugify
ModuleNotFoundError: No module named 'slugify'
ERROR 2021-03-15 20:51:18,204 log 632 139853666490176 Internal Server Error: / 
Traceback (most recent call last):
  File "/home/admintrud/.local/lib/python3.6/site-packages/django/core/handlers/exception.py", line 34, in inner
    response = get_response(request)
  File "/home/admintrud/.local/lib/python3.6/site-packages/django/core/handlers/base.py", line 100, in _get_response
    resolver_match = resolver.resolve(request.path_info)
  File "/home/admintrud/.local/lib/python3.6/site-packages/django/urls/resolvers.py", line 544, in resolve
    for pattern in self.url_patterns:
  File "/home/admintrud/.local/lib/python3.6/site-packages/django/utils/functional.py", line 48, in __get__
    res = instance.__dict__[self.name] = self.func(instance)
  File "/home/admintrud/.local/lib/python3.6/site-packages/django/urls/resolvers.py", line 588, in url_patterns
    patterns = getattr(self.urlconf_module, "urlpatterns", self.urlconf_module)
  File "/home/admintrud/.local/lib/python3.6/site-packages/django/utils/functional.py", line 48, in __get__
    res = instance.__dict__[self.name] = self.func(instance)
  File "/home/admintrud/.local/lib/python3.6/site-packages/django/urls/resolvers.py", line 581, in urlconf_module
    return import_module(self.urlconf_name)
  File "/usr/lib/python3.6/importlib/__init__.py", line 126, in import_module
    return _bootstrap._gcd_import(name[level:], package, level)
  File "<frozen importlib._bootstrap>", line 994, in _gcd_import
  File "<frozen importlib._bootstrap>", line 971, in _find_and_load
  File "<frozen importlib._bootstrap>", line 955, in _find_and_load_unlocked
  File "<frozen importlib._bootstrap>", line 665, in _load_unlocked
  File "<frozen importlib._bootstrap_external>", line 678, in exec_module
  File "<frozen importlib._bootstrap>", line 219, in _call_with_frames_removed
  File "/home/admintrud/front/shawarma_site/shawarma_site/urls.py", line 25, in <module>
    url(r'^customer_interface/', include('customer_interface.urls')),
  File "/home/admintrud/.local/lib/python3.6/site-packages/django/urls/conf.py", line 34, in include
    urlconf_module = import_module(urlconf_module)
  File "/usr/lib/python3.6/importlib/__init__.py", line 126, in import_module
    return _bootstrap._gcd_import(name[level:], package, level)
  File "<frozen importlib._bootstrap>", line 994, in _gcd_import
  File "<frozen importlib._bootstrap>", line 971, in _find_and_load
  File "<frozen importlib._bootstrap>", line 955, in _find_and_load_unlocked
  File "<frozen importlib._bootstrap>", line 665, in _load_unlocked
  File "<frozen importlib._bootstrap_external>", line 678, in exec_module
  File "<frozen importlib._bootstrap>", line 219, in _call_with_frames_removed
  File "/home/admintrud/front/shawarma_site/customer_interface/urls.py", line 3, in <module>
    from . import views
  File "/home/admintrud/front/shawarma_site/customer_interface/views.py", line 3, in <module>
    from slugify import slugify
ModuleNotFoundError: No module named 'slugify'
ERROR 2021-03-15 21:09:07,957 log 627 139853666490176 Internal Server Error: / 
Traceback (most recent call last):
  File "/home/admintrud/.local/lib/python3.6/site-packages/django/core/handlers/exception.py", line 34, in inner
    response = get_response(request)
  File "/home/admintrud/.local/lib/python3.6/site-packages/django/core/handlers/base.py", line 100, in _get_response
    resolver_match = resolver.resolve(request.path_info)
  File "/home/admintrud/.local/lib/python3.6/site-packages/django/urls/resolvers.py", line 544, in resolve
    for pattern in self.url_patterns:
  File "/home/admintrud/.local/lib/python3.6/site-packages/django/utils/functional.py", line 48, in __get__
    res = instance.__dict__[self.name] = self.func(instance)
  File "/home/admintrud/.local/lib/python3.6/site-packages/django/urls/resolvers.py", line 588, in url_patterns
    patterns = getattr(self.urlconf_module, "urlpatterns", self.urlconf_module)
  File "/home/admintrud/.local/lib/python3.6/site-packages/django/utils/functional.py", line 48, in __get__
    res = instance.__dict__[self.name] = self.func(instance)
  File "/home/admintrud/.local/lib/python3.6/site-packages/django/urls/resolvers.py", line 581, in urlconf_module
    return import_module(self.urlconf_name)
  File "/usr/lib/python3.6/importlib/__init__.py", line 126, in import_module
    return _bootstrap._gcd_import(name[level:], package, level)
  File "<frozen importlib._bootstrap>", line 994, in _gcd_import
  File "<frozen importlib._bootstrap>", line 971, in _find_and_load
  File "<frozen importlib._bootstrap>", line 955, in _find_and_load_unlocked
  File "<frozen importlib._bootstrap>", line 665, in _load_unlocked
  File "<frozen importlib._bootstrap_external>", line 678, in exec_module
  File "<frozen importlib._bootstrap>", line 219, in _call_with_frames_removed
  File "/home/admintrud/front/shawarma_site/shawarma_site/urls.py", line 25, in <module>
    url(r'^customer_interface/', include('customer_interface.urls')),
  File "/home/admintrud/.local/lib/python3.6/site-packages/django/urls/conf.py", line 34, in include
    urlconf_module = import_module(urlconf_module)
  File "/usr/lib/python3.6/importlib/__init__.py", line 126, in import_module
    return _bootstrap._gcd_import(name[level:], package, level)
  File "<frozen importlib._bootstrap>", line 994, in _gcd_import
  File "<frozen importlib._bootstrap>", line 971, in _find_and_load
  File "<frozen importlib._bootstrap>", line 955, in _find_and_load_unlocked
  File "<frozen importlib._bootstrap>", line 665, in _load_unlocked
  File "<frozen importlib._bootstrap_external>", line 678, in exec_module
  File "<frozen importlib._bootstrap>", line 219, in _call_with_frames_removed
  File "/home/admintrud/front/shawarma_site/customer_interface/urls.py", line 3, in <module>
    from . import views
  File "/home/admintrud/front/shawarma_site/customer_interface/views.py", line 3, in <module>
    from slugify import slugify
ModuleNotFoundError: No module named 'slugify'
ERROR 2021-03-16 13:25:31,197 log 1561 139865927276352 Internal Server Error: /customer_interface/basket 
Traceback (most recent call last):
  File "/home/admintrud/front/env/lib/python3.6/site-packages/django/core/handlers/exception.py", line 47, in inner
    response = get_response(request)
  File "/home/admintrud/front/env/lib/python3.6/site-packages/django/core/handlers/base.py", line 181, in _get_response
    response = wrapped_callback(request, *callback_args, **callback_kwargs)
  File "/home/admintrud/front/shawarma_site/customer_interface/views.py", line 134, in basket
    for item in current_order:
TypeError: 'NoneType' object is not iterable
ERROR 2021-03-16 13:25:31,317 log 1559 139865927276352 Internal Server Error: /customer_interface/basket 
Traceback (most recent call last):
  File "/home/admintrud/front/env/lib/python3.6/site-packages/django/core/handlers/exception.py", line 47, in inner
    response = get_response(request)
  File "/home/admintrud/front/env/lib/python3.6/site-packages/django/core/handlers/base.py", line 181, in _get_response
    response = wrapped_callback(request, *callback_args, **callback_kwargs)
  File "/home/admintrud/front/shawarma_site/customer_interface/views.py", line 134, in basket
    for item in current_order:
TypeError: 'NoneType' object is not iterable
ERROR 2021-03-16 13:25:31,423 log 1562 139865927276352 Internal Server Error: /customer_interface/basket 
Traceback (most recent call last):
  File "/home/admintrud/front/env/lib/python3.6/site-packages/django/core/handlers/exception.py", line 47, in inner
    response = get_response(request)
  File "/home/admintrud/front/env/lib/python3.6/site-packages/django/core/handlers/base.py", line 181, in _get_response
    response = wrapped_callback(request, *callback_args, **callback_kwargs)
  File "/home/admintrud/front/shawarma_site/customer_interface/views.py", line 134, in basket
    for item in current_order:
TypeError: 'NoneType' object is not iterable
ERROR 2021-03-16 13:26:07,072 log 1561 139865927276352 Internal Server Error: /customer_interface/basket 
Traceback (most recent call last):
  File "/home/admintrud/front/env/lib/python3.6/site-packages/django/core/handlers/exception.py", line 47, in inner
    response = get_response(request)
  File "/home/admintrud/front/env/lib/python3.6/site-packages/django/core/handlers/base.py", line 181, in _get_response
    response = wrapped_callback(request, *callback_args, **callback_kwargs)
  File "/home/admintrud/front/shawarma_site/customer_interface/views.py", line 134, in basket
    for item in current_order:
TypeError: 'NoneType' object is not iterable
ERROR 2021-03-16 13:26:07,183 log 1561 139865927276352 Internal Server Error: /customer_interface/basket 
Traceback (most recent call last):
  File "/home/admintrud/front/env/lib/python3.6/site-packages/django/core/handlers/exception.py", line 47, in inner
    response = get_response(request)
  File "/home/admintrud/front/env/lib/python3.6/site-packages/django/core/handlers/base.py", line 181, in _get_response
    response = wrapped_callback(request, *callback_args, **callback_kwargs)
  File "/home/admintrud/front/shawarma_site/customer_interface/views.py", line 134, in basket
    for item in current_order:
TypeError: 'NoneType' object is not iterable
ERROR 2021-03-16 13:26:07,279 log 1561 139865927276352 Internal Server Error: /customer_interface/basket 
Traceback (most recent call last):
  File "/home/admintrud/front/env/lib/python3.6/site-packages/django/core/handlers/exception.py", line 47, in inner
    response = get_response(request)
  File "/home/admintrud/front/env/lib/python3.6/site-packages/django/core/handlers/base.py", line 181, in _get_response
    response = wrapped_callback(request, *callback_args, **callback_kwargs)
  File "/home/admintrud/front/shawarma_site/customer_interface/views.py", line 134, in basket
    for item in current_order:
TypeError: 'NoneType' object is not iterable
ERROR 2021-03-17 20:05:28,049 log 1559 139865927276352 Internal Server Error: /customer_interface/basket 
Traceback (most recent call last):
  File "/home/admintrud/front/env/lib/python3.6/site-packages/django/core/handlers/exception.py", line 47, in inner
    response = get_response(request)
  File "/home/admintrud/front/env/lib/python3.6/site-packages/django/core/handlers/base.py", line 181, in _get_response
    response = wrapped_callback(request, *callback_args, **callback_kwargs)
  File "/home/admintrud/front/shawarma_site/customer_interface/views.py", line 134, in basket
    for item in current_order:
TypeError: 'NoneType' object is not iterable
ERROR 2021-03-19 21:46:21,378 log 1561 139865927276352 Internal Server Error: /customer_interface/basket 
Traceback (most recent call last):
  File "/home/admintrud/front/env/lib/python3.6/site-packages/django/core/handlers/exception.py", line 47, in inner
    response = get_response(request)
  File "/home/admintrud/front/env/lib/python3.6/site-packages/django/core/handlers/base.py", line 181, in _get_response
    response = wrapped_callback(request, *callback_args, **callback_kwargs)
  File "/home/admintrud/front/shawarma_site/customer_interface/views.py", line 134, in basket
    for item in current_order:
TypeError: 'NoneType' object is not iterable
ERROR 2021-03-22 19:40:48,632 log 1559 139865927276352 Internal Server Error: /customer_interface/basket 
Traceback (most recent call last):
  File "/home/admintrud/front/env/lib/python3.6/site-packages/django/core/handlers/exception.py", line 47, in inner
    response = get_response(request)
  File "/home/admintrud/front/env/lib/python3.6/site-packages/django/core/handlers/base.py", line 181, in _get_response
    response = wrapped_callback(request, *callback_args, **callback_kwargs)
  File "/home/admintrud/front/shawarma_site/customer_interface/views.py", line 134, in basket
    for item in current_order:
TypeError: 'NoneType' object is not iterable
ERROR 2021-03-26 13:46:25,489 log 1561 139865927276352 Internal Server Error: /customer_interface/basket 
Traceback (most recent call last):
  File "/home/admintrud/front/env/lib/python3.6/site-packages/django/core/handlers/exception.py", line 47, in inner
    response = get_response(request)
  File "/home/admintrud/front/env/lib/python3.6/site-packages/django/core/handlers/base.py", line 181, in _get_response
    response = wrapped_callback(request, *callback_args, **callback_kwargs)
  File "/home/admintrud/front/shawarma_site/customer_interface/views.py", line 134, in basket
    for item in current_order:
TypeError: 'NoneType' object is not iterable
ERROR 2021-04-03 22:55:46,748 log 1562 139865927276352 Internal Server Error: /customer_interface/basket 
Traceback (most recent call last):
  File "/home/admintrud/front/env/lib/python3.6/site-packages/django/core/handlers/exception.py", line 47, in inner
    response = get_response(request)
  File "/home/admintrud/front/env/lib/python3.6/site-packages/django/core/handlers/base.py", line 181, in _get_response
    response = wrapped_callback(request, *callback_args, **callback_kwargs)
  File "/home/admintrud/front/shawarma_site/customer_interface/views.py", line 134, in basket
    for item in current_order:
TypeError: 'NoneType' object is not iterable
ERROR 2021-04-04 03:36:01,146 log 1562 139865927276352 Internal Server Error: /customer_interface/basket 
Traceback (most recent call last):
  File "/home/admintrud/front/env/lib/python3.6/site-packages/django/core/handlers/exception.py", line 47, in inner
    response = get_response(request)
  File "/home/admintrud/front/env/lib/python3.6/site-packages/django/core/handlers/base.py", line 181, in _get_response
    response = wrapped_callback(request, *callback_args, **callback_kwargs)
  File "/home/admintrud/front/shawarma_site/customer_interface/views.py", line 134, in basket
    for item in current_order:
TypeError: 'NoneType' object is not iterable
ERROR 2021-04-06 23:35:08,112 log 1559 139865927276352 Internal Server Error: /customer_interface/basket 
Traceback (most recent call last):
  File "/home/admintrud/front/env/lib/python3.6/site-packages/django/core/handlers/exception.py", line 47, in inner
    response = get_response(request)
  File "/home/admintrud/front/env/lib/python3.6/site-packages/django/core/handlers/base.py", line 181, in _get_response
    response = wrapped_callback(request, *callback_args, **callback_kwargs)
  File "/home/admintrud/front/shawarma_site/customer_interface/views.py", line 134, in basket
    for item in current_order:
TypeError: 'NoneType' object is not iterable
ERROR 2021-04-06 23:40:00,060 log 1561 139865927276352 Internal Server Error: /customer_interface/basket 
Traceback (most recent call last):
  File "/home/admintrud/front/env/lib/python3.6/site-packages/django/core/handlers/exception.py", line 47, in inner
    response = get_response(request)
  File "/home/admintrud/front/env/lib/python3.6/site-packages/django/core/handlers/base.py", line 181, in _get_response
    response = wrapped_callback(request, *callback_args, **callback_kwargs)
  File "/home/admintrud/front/shawarma_site/customer_interface/views.py", line 134, in basket
    for item in current_order:
TypeError: 'NoneType' object is not iterable
ERROR 2021-04-07 00:46:43,150 log 1559 139865927276352 Internal Server Error: /customer_interface/basket 
Traceback (most recent call last):
  File "/home/admintrud/front/env/lib/python3.6/site-packages/django/core/handlers/exception.py", line 47, in inner
    response = get_response(request)
  File "/home/admintrud/front/env/lib/python3.6/site-packages/django/core/handlers/base.py", line 181, in _get_response
    response = wrapped_callback(request, *callback_args, **callback_kwargs)
  File "/home/admintrud/front/shawarma_site/customer_interface/views.py", line 134, in basket
    for item in current_order:
TypeError: 'NoneType' object is not iterable
ERROR 2021-04-07 00:46:46,716 log 1561 139865927276352 Internal Server Error: /customer_interface/basket 
Traceback (most recent call last):
  File "/home/admintrud/front/env/lib/python3.6/site-packages/django/core/handlers/exception.py", line 47, in inner
    response = get_response(request)
  File "/home/admintrud/front/env/lib/python3.6/site-packages/django/core/handlers/base.py", line 181, in _get_response
    response = wrapped_callback(request, *callback_args, **callback_kwargs)
  File "/home/admintrud/front/shawarma_site/customer_interface/views.py", line 134, in basket
    for item in current_order:
TypeError: 'NoneType' object is not iterable
ERROR 2021-04-08 18:58:08,828 log 1562 139865927276352 Internal Server Error: /customer_interface/basket 
Traceback (most recent call last):
  File "/home/admintrud/front/env/lib/python3.6/site-packages/django/core/handlers/exception.py", line 47, in inner
    response = get_response(request)
  File "/home/admintrud/front/env/lib/python3.6/site-packages/django/core/handlers/base.py", line 181, in _get_response
    response = wrapped_callback(request, *callback_args, **callback_kwargs)
  File "/home/admintrud/front/shawarma_site/customer_interface/views.py", line 134, in basket
    for item in current_order:
TypeError: 'NoneType' object is not iterable
ERROR 2021-04-09 14:18:17,223 log 1562 139865927276352 Internal Server Error: /customer_interface/basket 
Traceback (most recent call last):
  File "/home/admintrud/front/env/lib/python3.6/site-packages/django/core/handlers/exception.py", line 47, in inner
    response = get_response(request)
  File "/home/admintrud/front/env/lib/python3.6/site-packages/django/core/handlers/base.py", line 181, in _get_response
    response = wrapped_callback(request, *callback_args, **callback_kwargs)
  File "/home/admintrud/front/shawarma_site/customer_interface/views.py", line 134, in basket
    for item in current_order:
TypeError: 'NoneType' object is not iterable
ERROR 2021-04-18 11:18:53,321 log 1561 139865927276352 Internal Server Error: /customer_interface/basket 
Traceback (most recent call last):
  File "/home/admintrud/front/env/lib/python3.6/site-packages/django/core/handlers/exception.py", line 47, in inner
    response = get_response(request)
  File "/home/admintrud/front/env/lib/python3.6/site-packages/django/core/handlers/base.py", line 181, in _get_response
    response = wrapped_callback(request, *callback_args, **callback_kwargs)
  File "/home/admintrud/front/shawarma_site/customer_interface/views.py", line 134, in basket
    for item in current_order:
TypeError: 'NoneType' object is not iterable
ERROR 2022-03-09 22:38:17,692 log 659 140680152414016 Internal Server Error: /customer_interface/update_menu 
Traceback (most recent call last):
  File "/home/admintrud/front/env/lib/python3.6/site-packages/django/core/handlers/exception.py", line 47, in inner
    response = get_response(request)
  File "/home/admintrud/front/env/lib/python3.6/site-packages/sentry_sdk/integrations/django/middleware.py", line 175, in __call__
    return f(*args, **kwargs)
  File "/home/admintrud/front/env/lib/python3.6/site-packages/django/utils/deprecation.py", line 116, in __call__
    response = self.process_response(request, response)
  File "/home/admintrud/front/env/lib/python3.6/site-packages/django/middleware/common.py", line 106, in process_response
    if response.status_code == 404:
AttributeError: 'dict' object has no attribute 'status_code'
